155.33.135.24 - - [23/Nov/2022 14:30:52] "GET /- HTTP/1.1" 200 -
155.33.135.24 - - [23/Nov/2022 14:31:21] "GET /- HTTP/1.1" 200 -
----------------------------------------
Exception occurred during processing of request from ('155.33.135.24', 9287)
Traceback (most recent call last):
  File "/usr/lib/python3.10/socketserver.py", line 316, in _handle_request_noblock
    self.process_request(request, client_address)
  File "/usr/lib/python3.10/socketserver.py", line 347, in process_request
    self.finish_request(request, client_address)
  File "/usr/lib/python3.10/socketserver.py", line 360, in finish_request
    self.RequestHandlerClass(request, client_address, self)
  File "/usr/lib/python3.10/socketserver.py", line 747, in __init__
    self.handle()
  File "/usr/lib/python3.10/http/server.py", line 432, in handle
    self.handle_one_request()
  File "/usr/lib/python3.10/http/server.py", line 420, in handle_one_request
    method()
  File "/home/r_r/http_server/httpserver", line 23, in do_GET
    data = self.get_data(self.path)
  File "/home/r_r/http_server/httpserver", line 35, in get_data
    with urlopen("http://" + ORIGIN_SERVER + ":" + ORIGIN_PORT + path) as response:
  File "/usr/lib/python3.10/urllib/request.py", line 216, in urlopen
    return opener.open(url, data, timeout)
  File "/usr/lib/python3.10/urllib/request.py", line 525, in open
    response = meth(req, response)
  File "/usr/lib/python3.10/urllib/request.py", line 634, in http_response
    response = self.parent.error(
  File "/usr/lib/python3.10/urllib/request.py", line 563, in error
    return self._call_chain(*args)
  File "/usr/lib/python3.10/urllib/request.py", line 496, in _call_chain
    result = func(*args)
  File "/usr/lib/python3.10/urllib/request.py", line 643, in http_error_default
    raise HTTPError(req.full_url, code, msg, hdrs, fp)
urllib.error.HTTPError: HTTP Error 404: Not Found
----------------------------------------
----------------------------------------
Exception occurred during processing of request from ('155.33.135.24', 41259)
Traceback (most recent call last):
  File "/usr/lib/python3.10/socketserver.py", line 316, in _handle_request_noblock
    self.process_request(request, client_address)
  File "/usr/lib/python3.10/socketserver.py", line 347, in process_request
    self.finish_request(request, client_address)
  File "/usr/lib/python3.10/socketserver.py", line 360, in finish_request
    self.RequestHandlerClass(request, client_address, self)
  File "/usr/lib/python3.10/socketserver.py", line 747, in __init__
    self.handle()
  File "/usr/lib/python3.10/http/server.py", line 432, in handle
    self.handle_one_request()
  File "/usr/lib/python3.10/http/server.py", line 420, in handle_one_request
    method()
  File "/home/r_r/http_server/httpserver", line 23, in do_GET
    data = self.get_data(self.path)
  File "/home/r_r/http_server/httpserver", line 35, in get_data
    with urlopen("http://" + ORIGIN_SERVER + ":" + ORIGIN_PORT + path) as response:
  File "/usr/lib/python3.10/urllib/request.py", line 216, in urlopen
    return opener.open(url, data, timeout)
  File "/usr/lib/python3.10/urllib/request.py", line 525, in open
    response = meth(req, response)
  File "/usr/lib/python3.10/urllib/request.py", line 634, in http_response
    response = self.parent.error(
  File "/usr/lib/python3.10/urllib/request.py", line 563, in error
    return self._call_chain(*args)
  File "/usr/lib/python3.10/urllib/request.py", line 496, in _call_chain
    result = func(*args)
  File "/usr/lib/python3.10/urllib/request.py", line 643, in http_error_default
    raise HTTPError(req.full_url, code, msg, hdrs, fp)
urllib.error.HTTPError: HTTP Error 404: Not Found
----------------------------------------
----------------------------------------
Exception occurred during processing of request from ('155.33.135.24', 48910)
Traceback (most recent call last):
  File "/usr/lib/python3.10/socketserver.py", line 316, in _handle_request_noblock
    self.process_request(request, client_address)
  File "/usr/lib/python3.10/socketserver.py", line 347, in process_request
    self.finish_request(request, client_address)
  File "/usr/lib/python3.10/socketserver.py", line 360, in finish_request
    self.RequestHandlerClass(request, client_address, self)
  File "/usr/lib/python3.10/socketserver.py", line 747, in __init__
    self.handle()
  File "/usr/lib/python3.10/http/server.py", line 432, in handle
    self.handle_one_request()
  File "/usr/lib/python3.10/http/server.py", line 420, in handle_one_request
    method()
  File "/home/r_r/http_server/httpserver", line 23, in do_GET
    data = self.get_data(self.path)
  File "/home/r_r/http_server/httpserver", line 35, in get_data
    with urlopen("http://" + ORIGIN_SERVER + ":" + ORIGIN_PORT + path) as response:
  File "/usr/lib/python3.10/urllib/request.py", line 216, in urlopen
    return opener.open(url, data, timeout)
  File "/usr/lib/python3.10/urllib/request.py", line 525, in open
    response = meth(req, response)
  File "/usr/lib/python3.10/urllib/request.py", line 634, in http_response
    response = self.parent.error(
  File "/usr/lib/python3.10/urllib/request.py", line 563, in error
    return self._call_chain(*args)
  File "/usr/lib/python3.10/urllib/request.py", line 496, in _call_chain
    result = func(*args)
  File "/usr/lib/python3.10/urllib/request.py", line 643, in http_error_default
    raise HTTPError(req.full_url, code, msg, hdrs, fp)
urllib.error.HTTPError: HTTP Error 404: Not Found
----------------------------------------
----------------------------------------
Exception occurred during processing of request from ('155.33.135.24', 36190)
Traceback (most recent call last):
  File "/usr/lib/python3.10/socketserver.py", line 316, in _handle_request_noblock
    self.process_request(request, client_address)
  File "/usr/lib/python3.10/socketserver.py", line 347, in process_request
    self.finish_request(request, client_address)
  File "/usr/lib/python3.10/socketserver.py", line 360, in finish_request
    self.RequestHandlerClass(request, client_address, self)
  File "/usr/lib/python3.10/socketserver.py", line 747, in __init__
    self.handle()
  File "/usr/lib/python3.10/http/server.py", line 432, in handle
    self.handle_one_request()
  File "/usr/lib/python3.10/http/server.py", line 420, in handle_one_request
    method()
  File "/home/r_r/http_server/httpserver", line 23, in do_GET
    data = self.get_data(self.path)
  File "/home/r_r/http_server/httpserver", line 35, in get_data
    with urlopen("http://" + ORIGIN_SERVER + ":" + ORIGIN_PORT + path) as response:
  File "/usr/lib/python3.10/urllib/request.py", line 216, in urlopen
    return opener.open(url, data, timeout)
  File "/usr/lib/python3.10/urllib/request.py", line 525, in open
    response = meth(req, response)
  File "/usr/lib/python3.10/urllib/request.py", line 634, in http_response
    response = self.parent.error(
  File "/usr/lib/python3.10/urllib/request.py", line 563, in error
    return self._call_chain(*args)
  File "/usr/lib/python3.10/urllib/request.py", line 496, in _call_chain
    result = func(*args)
  File "/usr/lib/python3.10/urllib/request.py", line 643, in http_error_default
    raise HTTPError(req.full_url, code, msg, hdrs, fp)
urllib.error.HTTPError: HTTP Error 404: Not Found
----------------------------------------
----------------------------------------
Exception occurred during processing of request from ('155.33.135.24', 35982)
Traceback (most recent call last):
  File "/usr/lib/python3.10/socketserver.py", line 316, in _handle_request_noblock
    self.process_request(request, client_address)
  File "/usr/lib/python3.10/socketserver.py", line 347, in process_request
    self.finish_request(request, client_address)
  File "/usr/lib/python3.10/socketserver.py", line 360, in finish_request
    self.RequestHandlerClass(request, client_address, self)
  File "/usr/lib/python3.10/socketserver.py", line 747, in __init__
    self.handle()
  File "/usr/lib/python3.10/http/server.py", line 432, in handle
    self.handle_one_request()
  File "/usr/lib/python3.10/http/server.py", line 420, in handle_one_request
    method()
  File "/home/r_r/http_server/httpserver", line 23, in do_GET
    data = self.get_data(self.path)
  File "/home/r_r/http_server/httpserver", line 35, in get_data
    with urlopen("http://" + ORIGIN_SERVER + ":" + ORIGIN_PORT + path) as response:
  File "/usr/lib/python3.10/urllib/request.py", line 216, in urlopen
    return opener.open(url, data, timeout)
  File "/usr/lib/python3.10/urllib/request.py", line 525, in open
    response = meth(req, response)
  File "/usr/lib/python3.10/urllib/request.py", line 634, in http_response
    response = self.parent.error(
  File "/usr/lib/python3.10/urllib/request.py", line 563, in error
    return self._call_chain(*args)
  File "/usr/lib/python3.10/urllib/request.py", line 496, in _call_chain
    result = func(*args)
  File "/usr/lib/python3.10/urllib/request.py", line 643, in http_error_default
    raise HTTPError(req.full_url, code, msg, hdrs, fp)
urllib.error.HTTPError: HTTP Error 404: Not Found
----------------------------------------
----------------------------------------
Exception occurred during processing of request from ('155.33.135.24', 3227)
Traceback (most recent call last):
  File "/usr/lib/python3.10/socketserver.py", line 316, in _handle_request_noblock
    self.process_request(request, client_address)
  File "/usr/lib/python3.10/socketserver.py", line 347, in process_request
    self.finish_request(request, client_address)
  File "/usr/lib/python3.10/socketserver.py", line 360, in finish_request
    self.RequestHandlerClass(request, client_address, self)
  File "/usr/lib/python3.10/socketserver.py", line 747, in __init__
    self.handle()
  File "/usr/lib/python3.10/http/server.py", line 432, in handle
    self.handle_one_request()
  File "/usr/lib/python3.10/http/server.py", line 420, in handle_one_request
    method()
  File "/home/r_r/http_server/httpserver", line 23, in do_GET
    data = self.get_data(self.path)
  File "/home/r_r/http_server/httpserver", line 35, in get_data
    with urlopen("http://" + ORIGIN_SERVER + ":" + ORIGIN_PORT + path) as response:
  File "/usr/lib/python3.10/urllib/request.py", line 216, in urlopen
    return opener.open(url, data, timeout)
  File "/usr/lib/python3.10/urllib/request.py", line 525, in open
    response = meth(req, response)
  File "/usr/lib/python3.10/urllib/request.py", line 634, in http_response
    response = self.parent.error(
  File "/usr/lib/python3.10/urllib/request.py", line 563, in error
    return self._call_chain(*args)
  File "/usr/lib/python3.10/urllib/request.py", line 496, in _call_chain
    result = func(*args)
  File "/usr/lib/python3.10/urllib/request.py", line 643, in http_error_default
    raise HTTPError(req.full_url, code, msg, hdrs, fp)
urllib.error.HTTPError: HTTP Error 404: Not Found
----------------------------------------
----------------------------------------
Exception occurred during processing of request from ('155.33.135.24', 55047)
Traceback (most recent call last):
  File "/usr/lib/python3.10/socketserver.py", line 316, in _handle_request_noblock
    self.process_request(request, client_address)
  File "/usr/lib/python3.10/socketserver.py", line 347, in process_request
    self.finish_request(request, client_address)
  File "/usr/lib/python3.10/socketserver.py", line 360, in finish_request
    self.RequestHandlerClass(request, client_address, self)
  File "/usr/lib/python3.10/socketserver.py", line 747, in __init__
    self.handle()
  File "/usr/lib/python3.10/http/server.py", line 432, in handle
    self.handle_one_request()
  File "/usr/lib/python3.10/http/server.py", line 420, in handle_one_request
    method()
  File "/home/r_r/http_server/httpserver", line 23, in do_GET
    data = self.get_data(self.path)
  File "/home/r_r/http_server/httpserver", line 35, in get_data
    with urlopen("http://" + ORIGIN_SERVER + ":" + ORIGIN_PORT + path) as response:
  File "/usr/lib/python3.10/urllib/request.py", line 216, in urlopen
    return opener.open(url, data, timeout)
  File "/usr/lib/python3.10/urllib/request.py", line 525, in open
    response = meth(req, response)
  File "/usr/lib/python3.10/urllib/request.py", line 634, in http_response
    response = self.parent.error(
  File "/usr/lib/python3.10/urllib/request.py", line 563, in error
    return self._call_chain(*args)
  File "/usr/lib/python3.10/urllib/request.py", line 496, in _call_chain
    result = func(*args)
  File "/usr/lib/python3.10/urllib/request.py", line 643, in http_error_default
    raise HTTPError(req.full_url, code, msg, hdrs, fp)
urllib.error.HTTPError: HTTP Error 404: Not Found
----------------------------------------
----------------------------------------
Exception occurred during processing of request from ('155.33.135.24', 10390)
Traceback (most recent call last):
  File "/usr/lib/python3.10/socketserver.py", line 316, in _handle_request_noblock
    self.process_request(request, client_address)
  File "/usr/lib/python3.10/socketserver.py", line 347, in process_request
    self.finish_request(request, client_address)
  File "/usr/lib/python3.10/socketserver.py", line 360, in finish_request
    self.RequestHandlerClass(request, client_address, self)
  File "/usr/lib/python3.10/socketserver.py", line 747, in __init__
    self.handle()
  File "/usr/lib/python3.10/http/server.py", line 432, in handle
    self.handle_one_request()
  File "/usr/lib/python3.10/http/server.py", line 420, in handle_one_request
    method()
  File "/home/r_r/http_server/httpserver", line 23, in do_GET
    data = self.get_data(self.path)
  File "/home/r_r/http_server/httpserver", line 35, in get_data
    with urlopen("http://" + ORIGIN_SERVER + ":" + ORIGIN_PORT + path) as response:
  File "/usr/lib/python3.10/urllib/request.py", line 216, in urlopen
    return opener.open(url, data, timeout)
  File "/usr/lib/python3.10/urllib/request.py", line 525, in open
    response = meth(req, response)
  File "/usr/lib/python3.10/urllib/request.py", line 634, in http_response
    response = self.parent.error(
  File "/usr/lib/python3.10/urllib/request.py", line 563, in error
    return self._call_chain(*args)
  File "/usr/lib/python3.10/urllib/request.py", line 496, in _call_chain
    result = func(*args)
  File "/usr/lib/python3.10/urllib/request.py", line 643, in http_error_default
    raise HTTPError(req.full_url, code, msg, hdrs, fp)
urllib.error.HTTPError: HTTP Error 404: Not Found
----------------------------------------
----------------------------------------
Exception occurred during processing of request from ('155.33.135.24', 43561)
Traceback (most recent call last):
  File "/usr/lib/python3.10/socketserver.py", line 316, in _handle_request_noblock
    self.process_request(request, client_address)
  File "/usr/lib/python3.10/socketserver.py", line 347, in process_request
    self.finish_request(request, client_address)
  File "/usr/lib/python3.10/socketserver.py", line 360, in finish_request
    self.RequestHandlerClass(request, client_address, self)
  File "/usr/lib/python3.10/socketserver.py", line 747, in __init__
    self.handle()
  File "/usr/lib/python3.10/http/server.py", line 432, in handle
    self.handle_one_request()
  File "/usr/lib/python3.10/http/server.py", line 420, in handle_one_request
    method()
  File "/home/r_r/http_server/httpserver", line 23, in do_GET
    data = self.get_data(self.path)
  File "/home/r_r/http_server/httpserver", line 35, in get_data
    with urlopen("http://" + ORIGIN_SERVER + ":" + ORIGIN_PORT + path) as response:
  File "/usr/lib/python3.10/urllib/request.py", line 216, in urlopen
    return opener.open(url, data, timeout)
  File "/usr/lib/python3.10/urllib/request.py", line 525, in open
    response = meth(req, response)
  File "/usr/lib/python3.10/urllib/request.py", line 634, in http_response
    response = self.parent.error(
  File "/usr/lib/python3.10/urllib/request.py", line 563, in error
    return self._call_chain(*args)
  File "/usr/lib/python3.10/urllib/request.py", line 496, in _call_chain
    result = func(*args)
  File "/usr/lib/python3.10/urllib/request.py", line 643, in http_error_default
    raise HTTPError(req.full_url, code, msg, hdrs, fp)
urllib.error.HTTPError: HTTP Error 404: Not Found
----------------------------------------
----------------------------------------
Exception occurred during processing of request from ('155.33.135.24', 34427)
Traceback (most recent call last):
  File "/usr/lib/python3.10/socketserver.py", line 316, in _handle_request_noblock
    self.process_request(request, client_address)
  File "/usr/lib/python3.10/socketserver.py", line 347, in process_request
    self.finish_request(request, client_address)
  File "/usr/lib/python3.10/socketserver.py", line 360, in finish_request
    self.RequestHandlerClass(request, client_address, self)
  File "/usr/lib/python3.10/socketserver.py", line 747, in __init__
    self.handle()
  File "/usr/lib/python3.10/http/server.py", line 432, in handle
    self.handle_one_request()
  File "/usr/lib/python3.10/http/server.py", line 420, in handle_one_request
    method()
  File "/home/r_r/http_server/httpserver", line 23, in do_GET
    data = self.get_data(self.path)
  File "/home/r_r/http_server/httpserver", line 35, in get_data
    with urlopen("http://" + ORIGIN_SERVER + ":" + ORIGIN_PORT + path) as response:
  File "/usr/lib/python3.10/urllib/request.py", line 216, in urlopen
    return opener.open(url, data, timeout)
  File "/usr/lib/python3.10/urllib/request.py", line 525, in open
    response = meth(req, response)
  File "/usr/lib/python3.10/urllib/request.py", line 634, in http_response
    response = self.parent.error(
  File "/usr/lib/python3.10/urllib/request.py", line 563, in error
    return self._call_chain(*args)
  File "/usr/lib/python3.10/urllib/request.py", line 496, in _call_chain
    result = func(*args)
  File "/usr/lib/python3.10/urllib/request.py", line 643, in http_error_default
    raise HTTPError(req.full_url, code, msg, hdrs, fp)
urllib.error.HTTPError: HTTP Error 404: Not Found
----------------------------------------
----------------------------------------
Exception occurred during processing of request from ('155.33.135.24', 23817)
Traceback (most recent call last):
  File "/usr/lib/python3.10/socketserver.py", line 316, in _handle_request_noblock
    self.process_request(request, client_address)
  File "/usr/lib/python3.10/socketserver.py", line 347, in process_request
    self.finish_request(request, client_address)
  File "/usr/lib/python3.10/socketserver.py", line 360, in finish_request
    self.RequestHandlerClass(request, client_address, self)
  File "/usr/lib/python3.10/socketserver.py", line 747, in __init__
    self.handle()
  File "/usr/lib/python3.10/http/server.py", line 432, in handle
    self.handle_one_request()
  File "/usr/lib/python3.10/http/server.py", line 420, in handle_one_request
    method()
  File "/home/r_r/http_server/httpserver", line 23, in do_GET
    data = self.get_data(self.path)
  File "/home/r_r/http_server/httpserver", line 35, in get_data
    with urlopen("http://" + ORIGIN_SERVER + ":" + ORIGIN_PORT + path) as response:
  File "/usr/lib/python3.10/urllib/request.py", line 216, in urlopen
    return opener.open(url, data, timeout)
  File "/usr/lib/python3.10/urllib/request.py", line 525, in open
    response = meth(req, response)
  File "/usr/lib/python3.10/urllib/request.py", line 634, in http_response
    response = self.parent.error(
  File "/usr/lib/python3.10/urllib/request.py", line 563, in error
    return self._call_chain(*args)
  File "/usr/lib/python3.10/urllib/request.py", line 496, in _call_chain
    result = func(*args)
  File "/usr/lib/python3.10/urllib/request.py", line 643, in http_error_default
    raise HTTPError(req.full_url, code, msg, hdrs, fp)
urllib.error.HTTPError: HTTP Error 404: Not Found
----------------------------------------
----------------------------------------
Exception occurred during processing of request from ('155.33.135.24', 45157)
Traceback (most recent call last):
  File "/usr/lib/python3.10/socketserver.py", line 316, in _handle_request_noblock
    self.process_request(request, client_address)
  File "/usr/lib/python3.10/socketserver.py", line 347, in process_request
    self.finish_request(request, client_address)
  File "/usr/lib/python3.10/socketserver.py", line 360, in finish_request
    self.RequestHandlerClass(request, client_address, self)
  File "/usr/lib/python3.10/socketserver.py", line 747, in __init__
    self.handle()
  File "/usr/lib/python3.10/http/server.py", line 432, in handle
    self.handle_one_request()
  File "/usr/lib/python3.10/http/server.py", line 420, in handle_one_request
    method()
  File "/home/r_r/http_server/httpserver", line 23, in do_GET
    data = self.get_data(self.path)
  File "/home/r_r/http_server/httpserver", line 35, in get_data
    with urlopen("http://" + ORIGIN_SERVER + ":" + ORIGIN_PORT + path) as response:
  File "/usr/lib/python3.10/urllib/request.py", line 216, in urlopen
    return opener.open(url, data, timeout)
  File "/usr/lib/python3.10/urllib/request.py", line 525, in open
    response = meth(req, response)
  File "/usr/lib/python3.10/urllib/request.py", line 634, in http_response
    response = self.parent.error(
  File "/usr/lib/python3.10/urllib/request.py", line 563, in error
    return self._call_chain(*args)
  File "/usr/lib/python3.10/urllib/request.py", line 496, in _call_chain
    result = func(*args)
  File "/usr/lib/python3.10/urllib/request.py", line 643, in http_error_default
    raise HTTPError(req.full_url, code, msg, hdrs, fp)
urllib.error.HTTPError: HTTP Error 404: Not Found
----------------------------------------
----------------------------------------
Exception occurred during processing of request from ('155.33.135.24', 20704)
Traceback (most recent call last):
  File "/usr/lib/python3.10/socketserver.py", line 316, in _handle_request_noblock
    self.process_request(request, client_address)
  File "/usr/lib/python3.10/socketserver.py", line 347, in process_request
    self.finish_request(request, client_address)
  File "/usr/lib/python3.10/socketserver.py", line 360, in finish_request
    self.RequestHandlerClass(request, client_address, self)
  File "/usr/lib/python3.10/socketserver.py", line 747, in __init__
    self.handle()
  File "/usr/lib/python3.10/http/server.py", line 432, in handle
    self.handle_one_request()
  File "/usr/lib/python3.10/http/server.py", line 420, in handle_one_request
    method()
  File "/home/r_r/http_server/httpserver", line 23, in do_GET
    data = self.get_data(self.path)
  File "/home/r_r/http_server/httpserver", line 35, in get_data
    with urlopen("http://" + ORIGIN_SERVER + ":" + ORIGIN_PORT + path) as response:
  File "/usr/lib/python3.10/urllib/request.py", line 216, in urlopen
    return opener.open(url, data, timeout)
  File "/usr/lib/python3.10/urllib/request.py", line 525, in open
    response = meth(req, response)
  File "/usr/lib/python3.10/urllib/request.py", line 634, in http_response
    response = self.parent.error(
  File "/usr/lib/python3.10/urllib/request.py", line 563, in error
    return self._call_chain(*args)
  File "/usr/lib/python3.10/urllib/request.py", line 496, in _call_chain
    result = func(*args)
  File "/usr/lib/python3.10/urllib/request.py", line 643, in http_error_default
    raise HTTPError(req.full_url, code, msg, hdrs, fp)
urllib.error.HTTPError: HTTP Error 404: Not Found
----------------------------------------
----------------------------------------
Exception occurred during processing of request from ('155.33.135.24', 2875)
Traceback (most recent call last):
  File "/usr/lib/python3.10/socketserver.py", line 316, in _handle_request_noblock
    self.process_request(request, client_address)
  File "/usr/lib/python3.10/socketserver.py", line 347, in process_request
    self.finish_request(request, client_address)
  File "/usr/lib/python3.10/socketserver.py", line 360, in finish_request
    self.RequestHandlerClass(request, client_address, self)
  File "/usr/lib/python3.10/socketserver.py", line 747, in __init__
    self.handle()
  File "/usr/lib/python3.10/http/server.py", line 432, in handle
    self.handle_one_request()
  File "/usr/lib/python3.10/http/server.py", line 420, in handle_one_request
    method()
  File "/home/r_r/http_server/httpserver", line 23, in do_GET
    data = self.get_data(self.path)
  File "/home/r_r/http_server/httpserver", line 35, in get_data
    with urlopen("http://" + ORIGIN_SERVER + ":" + ORIGIN_PORT + path) as response:
  File "/usr/lib/python3.10/urllib/request.py", line 216, in urlopen
    return opener.open(url, data, timeout)
  File "/usr/lib/python3.10/urllib/request.py", line 525, in open
    response = meth(req, response)
  File "/usr/lib/python3.10/urllib/request.py", line 634, in http_response
    response = self.parent.error(
  File "/usr/lib/python3.10/urllib/request.py", line 563, in error
    return self._call_chain(*args)
  File "/usr/lib/python3.10/urllib/request.py", line 496, in _call_chain
    result = func(*args)
  File "/usr/lib/python3.10/urllib/request.py", line 643, in http_error_default
    raise HTTPError(req.full_url, code, msg, hdrs, fp)
urllib.error.HTTPError: HTTP Error 404: Not Found
----------------------------------------
----------------------------------------
Exception occurred during processing of request from ('155.33.135.24', 42507)
Traceback (most recent call last):
  File "/usr/lib/python3.10/socketserver.py", line 316, in _handle_request_noblock
    self.process_request(request, client_address)
  File "/usr/lib/python3.10/socketserver.py", line 347, in process_request
    self.finish_request(request, client_address)
  File "/usr/lib/python3.10/socketserver.py", line 360, in finish_request
    self.RequestHandlerClass(request, client_address, self)
  File "/usr/lib/python3.10/socketserver.py", line 747, in __init__
    self.handle()
  File "/usr/lib/python3.10/http/server.py", line 432, in handle
    self.handle_one_request()
  File "/usr/lib/python3.10/http/server.py", line 420, in handle_one_request
    method()
  File "/home/r_r/http_server/httpserver", line 23, in do_GET
    data = self.get_data(self.path)
  File "/home/r_r/http_server/httpserver", line 35, in get_data
    with urlopen("http://" + ORIGIN_SERVER + ":" + ORIGIN_PORT + path) as response:
  File "/usr/lib/python3.10/urllib/request.py", line 216, in urlopen
    return opener.open(url, data, timeout)
  File "/usr/lib/python3.10/urllib/request.py", line 525, in open
    response = meth(req, response)
  File "/usr/lib/python3.10/urllib/request.py", line 634, in http_response
    response = self.parent.error(
  File "/usr/lib/python3.10/urllib/request.py", line 563, in error
    return self._call_chain(*args)
  File "/usr/lib/python3.10/urllib/request.py", line 496, in _call_chain
    result = func(*args)
  File "/usr/lib/python3.10/urllib/request.py", line 643, in http_error_default
    raise HTTPError(req.full_url, code, msg, hdrs, fp)
urllib.error.HTTPError: HTTP Error 404: Not Found
----------------------------------------
